{"trial_id": "1", "hyperparameters": {"space": [{"class_name": "Int", "config": {"name": "units", "default": null, "conditions": [], "min_value": 32, "max_value": 128, "step": 32, "sampling": "linear"}}, {"class_name": "Choice", "config": {"name": "optimizer", "default": "adam", "conditions": [], "values": ["adam", "adadelta"], "ordered": false}}], "values": {"units": 64, "optimizer": "adadelta"}}, "metrics": {"metrics": {}}, "score": null, "best_step": 0, "status": "FAILED", "message": "Traceback (most recent call last):\n  File \"c:\\Users\\ppawa\\AppData\\Local\\Programs\\Python\\Python312\\Lib\\site-packages\\keras_tuner\\src\\engine\\base_tuner.py\", line 274, in _try_run_and_update_trial\n    self._run_and_update_trial(trial, *fit_args, **fit_kwargs)\n  File \"c:\\Users\\ppawa\\AppData\\Local\\Programs\\Python\\Python312\\Lib\\site-packages\\keras_tuner\\src\\engine\\base_tuner.py\", line 239, in _run_and_update_trial\n    results = self.run_trial(trial, *fit_args, **fit_kwargs)\n              ^^^^^^^^^^^^^^^^^^^^^^^^^^^^^^^^^^^^^^^^^^^^^^\n  File \"C:\\Users\\ppawa\\AppData\\Local\\Temp\\ipykernel_20400\\3589426549.py\", line 39, in run_trial\n    return keras_code(\n           ^^^^^^^^^^^\n  File \"C:\\Users\\ppawa\\AppData\\Local\\Temp\\ipykernel_20400\\3589426549.py\", line 27, in keras_code\n    model.save(saving_path)\n  File \"c:\\Users\\ppawa\\AppData\\Local\\Programs\\Python\\Python312\\Lib\\site-packages\\keras\\src\\utils\\traceback_utils.py\", line 122, in error_handler\n    raise e.with_traceback(filtered_tb) from None\n  File \"c:\\Users\\ppawa\\AppData\\Local\\Programs\\Python\\Python312\\Lib\\site-packages\\keras\\src\\saving\\saving_lib.py\", line 102, in save_model\n    with open(filepath, \"wb\") as f:\n         ^^^^^^^^^^^^^^^^^^^^\nOSError: [Errno 22] Invalid argument: '\\tmp\\\\1.keras'\n"}